Workbook

Sheet Raw Data
A1: Merchant | B1: Marketplace | C1: HO No | D1: HO Date | E1: User Id | F1: Cnote No | G1: Approved | H1: Shipment Type | I1: Cnote Amount | J1: Destination | K1: Service | L1: Qty | M1: Weight | N1: Cod Flag | O1: Ins Flag | P1: Goods Value | Q1: Created date | R1: Shipper Name | S1: Date_Str | T1: First_Occ | U1: Unique_Rank | V1: First_Occ_Cust | W1: Unique_Rank_Cust | X1: Marketplace_Clean
A2: SHOPEE SELLER | B2: 80514322-SHOPEE INTERNATIONAL | C2: HO-087-260731203448 | D2: 46234.857 | E2: ZKARNKRW | F2: 'CM46561385332 | G2: Y | H2: DROP | I2: 12000 | J2: CGK10108 | K2: REG23 | L2: 1 | M2: 0.1 | N2: N | O2: N | P2: 21500 | Q2: 46234.858 | R2: Ulfiyani | S2: =IF(Q2="","",TEXT(Q2,"yyyy-mm-dd")) -> 2026-07-31 | T2: =IF($E2="","",IF(COUNTIF($E$2:$E2,$E2)=1,1,0)) -> 1 | U2: =IF(T2=1,SUM($T$2:T2),"") -> 1 | V2: =IF(OR($R2="",$R2="-"),"",IF(COUNTIF($R$2:$R2,$R2)=1,1,0)) -> 1 | W2: =IF(V2=1,SUM($V$2:V2),"") -> 1 | X2: =IF(ISNUMBER(SEARCH("SHOPEE",B2)),"SHOPEE",IF(ISNUMBER(SEARCH("TOKOPEDIA",B2)),"TOKOPEDIA",IF(ISNUMBER(SEARCH("LASTANA",B2)),"LASTANA EXPRESS",IF(ISNUMBER(SEARCH("FASHION MARKETPLACE",B2)),"FASHION MARKETPLACE",IF(ISNUMBER(SEARCH("GLOBAL DIGITAL NIAGA",B2)),"GLOBAL DIGITAL NIAGA",IF(ISNUMBER(SEARCH("TOKGISTIC",B2)),"TOKGISTIC",IF(ISNUMBER(SEARCH("TOCO RAMAI",B2)),"TOCO RAMAI DIGITAL",B2))))))) -> SHOPEE
A3: SHOPEE SELLER | B3: 80514305-SHOPEE INTERNATIONAL | C3: HO-087-260731185443 | D3: 46234.787 | E3: RACHAYU | F3: 'CM05064746394 | G3: Y | H3: DROP | I3: 12000 | J3: TGR10128 | K3: REG23 | L3: 3 | M3: 0.3 | N3: N | O3: N | P3: 41460 | Q3: 46234.787 | R3: Maryani Yani/ mitra pompa | S3: =IF(Q3="","",TEXT(Q3,"yyyy-mm-dd")) -> 2026-07-31 | T3: =IF($E3="","",IF(COUNTIF($E$2:$E3,$E3)=1,1,0)) -> 1 | U3: =IF(T3=1,SUM($T$2:T3),"") -> 2 | V3: =IF(OR($R3="",$R3="-"),"",IF(COUNTIF($R$2:$R3,$R3)=1,1,0)) -> 1 | W3: =IF(V3=1,SUM($V$2:V3),"") -> 2 | X3: =IF(ISNUMBER(SEARCH("SHOPEE",B3)),"SHOPEE",IF(ISNUMBER(SEARCH("TOKOPEDIA",B3)),"TOKOPEDIA",IF(ISNUMBER(SEARCH("LASTANA",B3)),"LASTANA EXPRESS",IF(ISNUMBER(SEARCH("FASHION MARKETPLACE",B3)),"FASHION MARKETPLACE",IF(ISNUMBER(SEARCH("GLOBAL DIGITAL NIAGA",B3)),"GLOBAL DIGITAL NIAGA",IF(ISNUMBER(SEARCH("TOKGISTIC",B3)),"TOKGISTIC",IF(ISNUMBER(SEARCH("TOCO RAMAI",B3)),"TOCO RAMAI DIGITAL",B3))))))) -> SHOPEE
A4: SHOPEE SELLER | B4: 80514305-SHOPEE INTERNATIONAL | C4: HO-087-260731175023 | D4: 46234.743 | E4: ZKARNKRW | F4: 'CM47253813913 | G4: Y | H4: DROP | I4: 6000 | J4: BDO10046 | K4: REG05 | L4: 1 | M4: 0.17 | N4: N | O4: N | P4: 99 | Q4: 46234.743 | R4: Nadya Rameyza Elya | S4: =IF(Q4="","",TEXT(Q4,"yyyy-mm-dd")) -> 2026-07-31 | T4: =IF($E4="","",IF(COUNTIF($E$2:$E4,$E4)=1,1,0)) -> 0 | U4: =IF(T4=1,SUM($T$2:T4),"") | V4: =IF(OR($R4="",$R4="-"),"",IF(COUNTIF($R$2:$R4,$R4)=1,1,0)) -> 1 | W4: =IF(V4=1,SUM($V$2:V4),"") -> 3 | X4: =IF(ISNUMBER(SEARCH("SHOPEE",B4)),"SHOPEE",IF(ISNUMBER(SEARCH("TOKOPEDIA",B4)),"TOKOPEDIA",IF(ISNUMBER(SEARCH("LASTANA",B4)),"LASTANA EXPRESS",IF(ISNUMBER(SEARCH("FASHION MARKETPLACE",B4)),"FASHION MARKETPLACE",IF(ISNUMBER(SEARCH("GLOBAL DIGITAL NIAGA",B4)),"GLOBAL DIGITAL NIAGA",IF(ISNUMBER(SEARCH("TOKGISTIC",B4)),"TOKGISTIC",IF(ISNUMBER(SEARCH("TOCO RAMAI",B4)),"TOCO RAMAI DIGITAL",B4))))))) -> SHOPEE
A5: SHOPEE SELLER | B5: 80514305-SHOPEE INTERNATIONAL | C5: HO-087-260731175023 | D5: 46234.743 | E5: ZKARNKRW | F5: 'CM18878989182 | G5: Y | H5: DROP | I5: 6000 | J5: BDO10131 | K5: REG05 | L5: 1 | M5: 0.17 | N5: N | O5: N | P5: 99 | Q5: 46234.743 | R5: Nadya Rameyza Elya | S5: =IF(Q5="","",TEXT(Q5,"yyyy-mm-dd")) -> 2026-07-31 | T5: =IF($E5="","",IF(COUNTIF($E$2:$E5,$E5)=1,1,0)) -> 0 | U5: =IF(T5=1,SUM($T$2:T5),"") | V5: =IF(OR($R5="",$R5="-"),"",IF(COUNTIF($R$2:$R5,$R5)=1,1,0)) -> 0 | W5: =IF(V5=1,SUM($V$2:V5),"") | X5: =IF(ISNUMBER(SEARCH("SHOPEE",B5)),"SHOPEE",IF(ISNUMBER(SEARCH("TOKOPEDIA",B5)),"TOKOPEDIA",IF(ISNUMBER(SEARCH("LASTANA",B5)),"LASTANA EXPRESS",IF(ISNUMBER(SEARCH("FASHION MARKETPLACE",B5)),"FASHION MARKETPLACE",IF(ISNUMBER(SEARCH("GLOBAL DIGITAL NIAGA",B5)),"GLOBAL DIGITAL NIAGA",IF(ISNUMBER(SEARCH("TOKGISTIC",B5)),"TOKGISTIC",IF(ISNUMBER(SEARCH("TOCO RAMAI",B5)),"TOCO RAMAI DIGITAL",B5))))))) -> SHOPEE
A6: SHOPEE SELLER | B6: 80514305-SHOPEE INTERNATIONAL | C6: HO-087-260731173734 | D6: 46234.734 | E6: ZKARNKRW | F6: 'CM49138065854 | G6: Y | H6: DROP | I6: 29000 | J6: MXG20306 | K6: REG23 | L6: 2 | M6: 0.39 | N6: N | O6: N | P6: 258110 | Q6: 46234.734 | R6: Nuraya Active | S6: =IF(Q6="","",TEXT(Q6,"yyyy-mm-dd")) -> 2026-07-31 | T6: =IF($E6="","",IF(COUNTIF($E$2:$E6,$E6)=1,1,0)) -> 0 | U6: =IF(T6=1,SUM($T$2:T6),"") | V6: =IF(OR($R6="",$R6="-"),"",IF(COUNTIF($R$2:$R6,$R6)=1,1,0)) -> 1 | W6: =IF(V6=1,SUM($V$2:V6),"") -> 4 | X6: =IF(ISNUMBER(SEARCH("SHOPEE",B6)),"SHOPEE",IF(ISNUMBER(SEARCH("TOKOPEDIA",B6)),"TOKOPEDIA",IF(ISNUMBER(SEARCH("LASTANA",B6)),"LASTANA EXPRESS",IF(ISNUMBER(SEARCH("FASHION MARKETPLACE",B6)),"FASHION MARKETPLACE",IF(ISNUMBER(SEARCH("GLOBAL DIGITAL NIAGA",B6)),"GLOBAL DIGITAL NIAGA",IF(ISNUMBER(SEARCH("TOKGISTIC",B6)),"TOKGISTIC",IF(ISNUMBER(SEARCH("TOCO RAMAI",B6)),"TOCO RAMAI DIGITAL",B6))))))) -> SHOPEE
A7: SHOPEE SELLER | B7: 80514305-SHOPEE INTERNATIONAL | C7: HO-087-260731170010 | D7: 46234.708 | E7: RACHAYU | F7: 'CM22545949075 | G7: Y | H7: DROP | I7: 12000 | J7: BOO20120 | K7: REG23 | L7: 1 | M7: 0.3 | N7: N | O7: N | P7: 27000 | Q7: 46234.708 | R7: Dani Hamdani (Yasashi Japan) | S7: =IF(Q7="","",TEXT(Q7,"yyyy-mm-dd")) -> 2026-07-31 | T7: =IF($E7="","",IF(COUNTIF($E$2:$E7,$E7)=1,1,0)) -> 0 | U7: =IF(T7=1,SUM($T$2:T7),"") | V7: =IF(OR($R7="",$R7="-"),"",IF(COUNTIF($R$2:$R7,$R7)=1,1,0)) -> 1 | W7: =IF(V7=1,SUM($V$2:V7),"") -> 5 | X7: =IF(ISNUMBER(SEARCH("SHOPEE",B7)),"SHOPEE",IF(ISNUMBER(SEARCH("TOKOPEDIA",B7)),"TOKOPEDIA",IF(ISNUMBER(SEARCH("LASTANA",B7)),"LASTANA EXPRESS",IF(ISNUMBER(SEARCH("FASHION MARKETPLACE",B7)),"FASHION MARKETPLACE",IF(ISNUMBER(SEARCH("GLOBAL DIGITAL NIAGA",B7)),"GLOBAL DIGITAL NIAGA",IF(ISNUMBER(SEARCH("TOKGISTIC",B7)),"TOKGISTIC",IF(ISNUMBER(SEARCH("TOCO RAMAI",B7)),"TOCO RAMAI DIGITAL",B7))))))) -> SHOPEE
A8: SHOPEE SELLER | B8: 80514305-SHOPEE INTERNATIONAL | C8: HO-087-260731170010 | D8: 46234.708 | E8: RACHAYU | F8: 'CM01802847899 | G8: Y | H8: DROP | I8: 48000 | J8: BKI10122 | K8: REG23 | L8: 5 | M8: 3.6 | N8: N | O8: N | P8: 570000 | Q8: 46234.708 | R8: Michael L. | S8: =IF(Q8="","",TEXT(Q8,"yyyy-mm-dd")) -> 2026-07-31 | T8: =IF($E8="","",IF(COUNTIF($E$2:$E8,$E8)=1,1,0)) -> 0 | U8: =IF(T8=1,SUM($T$2:T8),"") | V8: =IF(OR($R8="",$R8="-"),"",IF(COUNTIF($R$2:$R8,$R8)=1,1,0)) -> 1 | W8: =IF(V8=1,SUM($V$2:V8),"") -> 6 | X8: =IF(ISNUMBER(SEARCH("SHOPEE",B8)),"SHOPEE",IF(ISNUMBER(SEARCH("TOKOPEDIA",B8)),"TOKOPEDIA",IF(ISNUMBER(SEARCH("LASTANA",B8)),"LASTANA EXPRESS",IF(ISNUMBER(SEARCH("FASHION MARKETPLACE",B8)),"FASHION MARKETPLACE",IF(ISNUMBER(SEARCH("GLOBAL DIGITAL NIAGA",B8)),"GLOBAL DIGITAL NIAGA",IF(ISNUMBER(SEARCH("TOKGISTIC",B8)),"TOKGISTIC",IF(ISNUMBER(SEARCH("TOCO RAMAI",B8)),"TOCO RAMAI DIGITAL",B8))))))) -> SHOPEE
A9: SJM PAPER STICKER | B9: 80561601-TOKOPEDIA PT | C9: HO-087-260731170010 | D9: 46234.708 | E9: RACHAYU | F9: 'TG7006468835 | G9: Y | H9: DROP | I9: 12000 | J9: CGK10406 | K9: REG23 | L9: 1 | M9: 0.34 | N9: N | O9: N | P9: 228000 | Q9: 46234.708 | R9: MICHAEL LONDA | S9: =IF(Q9="","",TEXT(Q9,"yyyy-mm-dd")) -> 2026-07-31 | T9: =IF($E9="","",IF(COUNTIF($E$2:$E9,$E9)=1,1,0)) -> 0 | U9: =IF(T9=1,SUM($T$2:T9),"") | V9: =IF(OR($R9="",$R9="-"),"",IF(COUNTIF($R$2:$R9,$R9)=1,1,0)) -> 1 | W9: =IF(V9=1,SUM($V$2:V9),"") -> 7 | X9: =IF(ISNUMBER(SEARCH("SHOPEE",B9)),"SHOPEE",IF(ISNUMBER(SEARCH("TOKOPEDIA",B9)),"TOKOPEDIA",IF(ISNUMBER(SEARCH("LASTANA",B9)),"LASTANA EXPRESS",IF(ISNUMBER(SEARCH("FASHION MARKETPLACE",B9)),"FASHION MARKETPLACE",IF(ISNUMBER(SEARCH("GLOBAL DIGITAL NIAGA",B9)),"GLOBAL DIGITAL NIAGA",IF(ISNUMBER(SEARCH("TOKGISTIC",B9)),"TOKGISTIC",IF(ISNUMBER(SEARCH("TOCO RAMAI",B9)),"TOCO RAMAI DIGITAL",B9))))))) -> TOKOPEDIA
A10: SHOPEE SELLER | B10: 80514305-SHOPEE INTERNATIONAL | C10: HO-087-260731170010 | D10: 46234.708 | E10: RACHAYU | F10: 'CM56176526013 | G10: Y | H10: DROP | I10: 12000 | J10: DPK10059 | K10: REG23 | L10: 1 | M10: 0.72 | N10: N | O10: N | P10: 114000 | Q10: 46234.708 | R10: Michael L. | S10: =IF(Q10="","",TEXT(Q10,"yyyy-mm-dd")) -> 2026-07-31 | T10: =IF($E10="","",IF(COUNTIF($E$2:$E10,$E10)=1,1,0)) -> 0 | U10: =IF(T10=1,SUM($T$2:T10),"") | V10: =IF(OR($R10="",$R10="-"),"",IF(COUNTIF($R$2:$R10,$R10)=1,1,0)) -> 0 | W10: =IF(V10=1,SUM($V$2:V10),"") | X10: =IF(ISNUMBER(SEARCH("SHOPEE",B10)),"SHOPEE",IF(ISNUMBER(SEARCH("TOKOPEDIA",B10)),"TOKOPEDIA",IF(ISNUMBER(SEARCH("LASTANA",B10)),"LASTANA EXPRESS",IF(ISNUMBER(SEARCH("FASHION MARKETPLACE",B10)),"FASHION MARKETPLACE",IF(ISNUMBER(SEARCH("GLOBAL DIGITAL NIAGA",B10)),"GLOBAL DIGITAL NIAGA",IF(ISNUMBER(SEARCH("TOKGISTIC",B10)),"TOKGISTIC",IF(ISNUMBER(SEARCH("TOCO RAMAI",B10)),"TOCO RAMAI DIGITAL",B10))))))) -> SHOPEE
A11: SHOPEE SELLER | B11: 80514305-SHOPEE INTERNATIONAL | C11: HO-087-260731170010 | D11: 46234.708 | E11: RACHAYU | F11: 'CM59602242408 | G11: Y | H11: DROP | I11: 68000 | J11: DPS21100 | K11: REG23 | L11: 20 | M11: 1.6 | N11: N | O11: N | P11: 734000 | Q11: 46234.708 | R11: Michael L. | S11: =IF(Q11="","",TEXT(Q11,"yyyy-mm-dd")) -> 2026-07-31 | T11: =IF($E11="","",IF(COUNTIF($E$2:$E11,$E11)=1,1,0)) -> 0 | U11: =IF(T11=1,SUM($T$2:T11),"") | V11: =IF(OR($R11="",$R11="-"),"",IF(COUNTIF($R$2:$R11,$R11)=1,1,0)) -> 0 | W11: =IF(V11=1,SUM($V$2:V11),"") | X11: =IF(ISNUMBER(SEARCH("SHOPEE",B11)),"SHOPEE",IF(ISNUMBER(SEARCH("TOKOPEDIA",B11)),"TOKOPEDIA",IF(ISNUMBER(SEARCH("LASTANA",B11)),"LASTANA EXPRESS",IF(ISNUMBER(SEARCH("FASHION MARKETPLACE",B11)),"FASHION MARKETPLACE",IF(ISNUMBER(SEARCH("GLOBAL DIGITAL NIAGA",B11)),"GLOBAL DIGITAL NIAGA",IF(ISNUMBER(SEARCH("TOKGISTIC",B11)),"TOKGISTIC",IF(ISNUMBER(SEARCH("TOCO RAMAI",B11)),"TOCO RAMAI DIGITAL",B11))))))) -> SHOPEE
A12: SHOPEE SELLER | B12: 80514305-SHOPEE INTERNATIONAL | C12: HO-087-260731170010 | D12: 46234.708 | E12: RACHAYU | F12: 'JY99402703895 | G12: Y | H12: DROP | I12: 18000 | J12: DPK10059 | K12: YES23 | L12: 1 | M12: 0.13 | N12: N | O12: N | P12: 23620 | Q12: 46234.708 | R12: Yasashi Japan Shop | S12: =IF(Q12="","",TEXT(Q12,"yyyy-mm-dd")) -> 2026-07-31 | T12: =IF($E12="","",IF(COUNTIF($E$2:$E12,$E12)=1,1,0)) -> 0 | U12: =IF(T12=1,SUM($T$2:T12),"") | V12: =IF(OR($R12="",$R12="-"),"",IF(COUNTIF($R$2:$R12,$R12)=1,1,0)) -> 1 | W12: =IF(V12=1,SUM($V$2:V12),"") -> 8 | X12: =IF(ISNUMBER(SEARCH("SHOPEE",B12)),"SHOPEE",IF(ISNUMBER(SEARCH("TOKOPEDIA",B12)),"TOKOPEDIA",IF(ISNUMBER(SEARCH("LASTANA",B12)),"LASTANA EXPRESS",IF(ISNUMBER(SEARCH("FASHION MARKETPLACE",B12)),"FASHION MARKETPLACE",IF(ISNUMBER(SEARCH("GLOBAL DIGITAL NIAGA",B12)),"GLOBAL DIGITAL NIAGA",IF(ISNUMBER(SEARCH("TOKGISTIC",B12)),"TOKGISTIC",IF(ISNUMBER(SEARCH("TOCO RAMAI",B12)),"TOCO RAMAI DIGITAL",B12))))))) -> SHOPEE
A13: SHOPEE SELLER | B13: 80514305-SHOPEE INTERNATIONAL | C13: HO-087-260731170010 | D13: 46234.708 | E13: RACHAYU | F13: 'JY52936873154 | G13: Y | H13: DROP | I13: 18000 | J13: BKI10048 | K13: YES23 | L13: 1 | M13: 0.13 | N13: N | O13: N | P13: 24000 | Q13: 46234.708 | R13: Yasashi Japan Shop | S13: =IF(Q13="","",TEXT(Q13,"yyyy-mm-dd")) -> 2026-07-31 | T13: =IF($E13="","",IF(COUNTIF($E$2:$E13,$E13)=1,1,0)) -> 0 | U13: =IF(T13=1,SUM($T$2:T13),"") | V13: =IF(OR($R13="",$R13="-"),"",IF(COUNTIF($R$2:$R13,$R13)=1,1,0)) -> 0 | W13: =IF(V13=1,SUM($V$2:V13),"") | X13: =IF(ISNUMBER(SEARCH("SHOPEE",B13)),"SHOPEE",IF(ISNUMBER(SEARCH("TOKOPEDIA",B13)),"TOKOPEDIA",IF(ISNUMBER(SEARCH("LASTANA",B13)),"LASTANA EXPRESS",IF(ISNUMBER(SEARCH("FASHION MARKETPLACE",B13)),"FASHION MARKETPLACE",IF(ISNUMBER(SEARCH("GLOBAL DIGITAL NIAGA",B13)),"GLOBAL DIGITAL NIAGA",IF(ISNUMBER(SEARCH("TOKGISTIC",B13)),"TOKGISTIC",IF(ISNUMBER(SEARCH("TOCO RAMAI",B13)),"TOCO RAMAI DIGITAL",B13))))))) -> SHOPEE
... A691: SHOPEE SELLER | B691: 80514305-SHOPEE INTERNATIONAL | C691: HO-087-260701121631 | D691: 46204.511 | E691: NAFARA | F691: 'CM72906276302 | G691: Y | H691: DROP | I691: 24000 | J691: SRG22201 | K691: REG23 | L691: 1 | M691: 1 | N691: N | O691: N | P691: 45500 | Q691: 46204.512 | R691: Dela Natalia Saputra | S691: =IF(Q691="","",TEXT(Q691,"yyyy-mm-dd")) -> 2026-07-01 | T691: =IF($E691="","",IF(COUNTIF($E$2:$E691,$E691)=1,1,0)) -> 0 | U691: =IF(T691=1,SUM($T$2:T691),"") | V691: =IF(OR($R691="",$R691="-"),"",IF(COUNTIF($R$2:$R691,$R691)=1,1,0)) -> 0 | W691: =IF(V691=1,SUM($V$2:V691),"") | X691: =IF(ISNUMBER(SEARCH("SHOPEE",B691)),"SHOPEE",IF(ISNUMBER(SEARCH("TOKOPEDIA",B691)),"TOKOPEDIA",IF(ISNUMBER(SEARCH("LASTANA",B691)),"LASTANA EXPRESS",IF(ISNUMBER(SEARCH("FASHION MARKETPLACE",B691)),"FASHION MARKETPLACE",IF(ISNUMBER(SEARCH("GLOBAL DIGITAL NIAGA",B691)),"GLOBAL DIGITAL NIAGA",IF(ISNUMBER(SEARCH("TOKGISTIC",B691)),"TOKGISTIC",IF(ISNUMBER(SEARCH("TOCO RAMAI",B691)),"TOCO RAMAI DIGITAL",B691))))))) -> SHOPEE
S692: =IF(Q692="","",TEXT(Q692,"yyyy-mm-dd")) | T692: =IF($E692="","",IF(COUNTIF($E$2:$E692,$E692)=1,1,0)) | U692: =IF(T692=1,SUM($T$2:T692),"") | V692: =IF(OR($R692="",$R692="-"),"",IF(COUNTIF($R$2:$R692,$R692)=1,1,0)) | W692: =IF(V692=1,SUM($V$2:V692),"") | X692: =IF(ISNUMBER(SEARCH("SHOPEE",B692)),"SHOPEE",IF(ISNUMBER(SEARCH("TOKOPEDIA",B692)),"TOKOPEDIA",IF(ISNUMBER(SEARCH("LASTANA",B692)),"LASTANA EXPRESS",IF(ISNUMBER(SEARCH("FASHION MARKETPLACE",B692)),"FASHION MARKETPLACE",IF(ISNUMBER(SEARCH("GLOBAL DIGITAL NIAGA",B692)),"GLOBAL DIGITAL NIAGA",IF(ISNUMBER(SEARCH("TOKGISTIC",B692)),"TOKGISTIC",IF(ISNUMBER(SEARCH("TOCO RAMAI",B692)),"TOCO RAMAI DIGITAL",B692))))))) -> 0
S693: =IF(Q693="","",TEXT(Q693,"yyyy-mm-dd")) | T693: =IF($E693="","",IF(COUNTIF($E$2:$E693,$E693)=1,1,0)) | U693: =IF(T693=1,SUM($T$2:T693),"") | V693: =IF(OR($R693="",$R693="-"),"",IF(COUNTIF($R$2:$R693,$R693)=1,1,0)) | W693: =IF(V693=1,SUM($V$2:V693),"") | X693: =IF(ISNUMBER(SEARCH("SHOPEE",B693)),"SHOPEE",IF(ISNUMBER(SEARCH("TOKOPEDIA",B693)),"TOKOPEDIA",IF(ISNUMBER(SEARCH("LASTANA",B693)),"LASTANA EXPRESS",IF(ISNUMBER(SEARCH("FASHION MARKETPLACE",B693)),"FASHION MARKETPLACE",IF(ISNUMBER(SEARCH("GLOBAL DIGITAL NIAGA",B693)),"GLOBAL DIGITAL NIAGA",IF(ISNUMBER(SEARCH("TOKGISTIC",B693)),"TOKGISTIC",IF(ISNUMBER(SEARCH("TOCO RAMAI",B693)),"TOCO RAMAI DIGITAL",B693))))))) -> 0
S694: =IF(Q694="","",TEXT(Q694,"yyyy-mm-dd")) | T694: =IF($E694="","",IF(COUNTIF($E$2:$E694,$E694)=1,1,0)) | U694: =IF(T694=1,SUM($T$2:T694),"") | V694: =IF(OR($R694="",$R694="-"),"",IF(COUNTIF($R$2:$R694,$R694)=1,1,0)) | W694: =IF(V694=1,SUM($V$2:V694),"") | X694: =IF(ISNUMBER(SEARCH("SHOPEE",B694)),"SHOPEE",IF(ISNUMBER(SEARCH("TOKOPEDIA",B694)),"TOKOPEDIA",IF(ISNUMBER(SEARCH("LASTANA",B694)),"LASTANA EXPRESS",IF(ISNUMBER(SEARCH("FASHION MARKETPLACE",B694)),"FASHION MARKETPLACE",IF(ISNUMBER(SEARCH("GLOBAL DIGITAL NIAGA",B694)),"GLOBAL DIGITAL NIAGA",IF(ISNUMBER(SEARCH("TOKGISTIC",B694)),"TOKGISTIC",IF(ISNUMBER(SEARCH("TOCO RAMAI",B694)),"TOCO RAMAI DIGITAL",B694))))))) -> 0
S695: =IF(Q695="","",TEXT(Q695,"yyyy-mm-dd")) | T695: =IF($E695="","",IF(COUNTIF($E$2:$E695,$E695)=1,1,0)) | U695: =IF(T695=1,SUM($T$2:T695),"") | V695: =IF(OR($R695="",$R695="-"),"",IF(COUNTIF($R$2:$R695,$R695)=1,1,0)) | W695: =IF(V695=1,SUM($V$2:V695),"") | X695: =IF(ISNUMBER(SEARCH("SHOPEE",B695)),"SHOPEE",IF(ISNUMBER(SEARCH("TOKOPEDIA",B695)),"TOKOPEDIA",IF(ISNUMBER(SEARCH("LASTANA",B695)),"LASTANA EXPRESS",IF(ISNUMBER(SEARCH("FASHION MARKETPLACE",B695)),"FASHION MARKETPLACE",IF(ISNUMBER(SEARCH("GLOBAL DIGITAL NIAGA",B695)),"GLOBAL DIGITAL NIAGA",IF(ISNUMBER(SEARCH("TOKGISTIC",B695)),"TOKGISTIC",IF(ISNUMBER(SEARCH("TOCO RAMAI",B695)),"TOCO RAMAI DIGITAL",B695))))))) -> 0
S696: =IF(Q696="","",TEXT(Q696,"yyyy-mm-dd")) | T696: =IF($E696="","",IF(COUNTIF($E$2:$E696,$E696)=1,1,0)) | U696: =IF(T696=1,SUM($T$2:T696),"") | V696: =IF(OR($R696="",$R696="-"),"",IF(COUNTIF($R$2:$R696,$R696)=1,1,0)) | W696: =IF(V696=1,SUM($V$2:V696),"") | X696: =IF(ISNUMBER(SEARCH("SHOPEE",B696)),"SHOPEE",IF(ISNUMBER(SEARCH("TOKOPEDIA",B696)),"TOKOPEDIA",IF(ISNUMBER(SEARCH("LASTANA",B696)),"LASTANA EXPRESS",IF(ISNUMBER(SEARCH("FASHION MARKETPLACE",B696)),"FASHION MARKETPLACE",IF(ISNUMBER(SEARCH("GLOBAL DIGITAL NIAGA",B696)),"GLOBAL DIGITAL NIAGA",IF(ISNUMBER(SEARCH("TOKGISTIC",B696)),"TOKGISTIC",IF(ISNUMBER(SEARCH("TOCO RAMAI",B696)),"TOCO RAMAI DIGITAL",B696))))))) -> 0

Sheet Dashboard
A1: 📊 DASHBOARD PERFORMA PENGIRIMAN CASHLESS
A2: ="Periode: "&TEXT(MAX('Raw Data'!$Q$2:$Q$50000),"MMMM YYYY")&" " -> Periode: July 2026
A4: 📦 TOTAL TRANSAKSI | C4: 💰 TOTAL PENDAPATAN | E4: 📈 RATA-RATA/TRANSAKSI | G4: ⚖️ TOTAL BERAT (KG)
A5: =SUM('Rekap User'!B4:B11) -> 690 | C5: =SUM('Rekap User'!C4:C11) -> 19874000 | E5: =IFERROR(SUM('Rekap User'!C4:C11)/SUM('Rekap User'!B4:B11),0) -> 28802.899 | G5: =SUM('Raw Data'!$M$2:$M$50000) -> 1317.65
A7: 🏆 SCO TERBAIK | C7: 👥 SCO AKTIF BULAN INI | E7: 🚚 LAYANAN TERLARIS | G7: 🛒 MARKETPLACE FAVORIT
A8: =INDEX('Rekap User'!$A$4:$A$11,MATCH(1,'Rekap User'!$D$4:$D$11,0))&" — Rp"&TEXT(INDEX('Rekap User'!$C$4:$C$11,MATCH(1,'Rekap User'!$D$4:$D$11,0)),"#,##0") -> FATAPE — Rp8,681,000 | C8: =SUMPRODUCT(--('Rekap User'!$A$4:$A$11<>""))&" orang" -> 4 orang | E8: =INDEX('Rekap Service'!$A$4:$A$11,MATCH(MAX('Rekap Service'!$C$4:$C$11),'Rekap Service'!$C$4:$C$11,0)) -> REG23 | G8: =INDEX('Rekap Marketplace'!$A$5:$A$11,MATCH(MAX('Rekap Marketplace'!$C$5:$C$11),'Rekap Marketplace'!$C$5:$C$11,0)) -> SHOPEE
A10: 📊 Tren & Distribusi

Sheet Rekap User
A1: 👤 REKAP PERFORMA SCO
A3: User id | B3: Total_Transaksi | C3: Total_Pendapatan | D3: Rank_Pendapatan
A4: =IFERROR(INDEX('Raw Data'!$E$2:$E$50000,MATCH(1,'Raw Data'!$U$2:$U$50000,0)),"") -> ZKARNKRW | B4: =IF($A4="","",COUNTIFS('Raw Data'!$E$2:$E$50000,$A4)) -> 179 | C4: =IF($A4="","",SUMIFS('Raw Data'!$I$2:$I$50000,'Raw Data'!$E$2:$E$50000,$A4)) -> 3870000 | D4: =IF($A4="","",RANK($C4,$C$4:$C$11)+COUNTIF($C$4:C4,$C4)-1) -> 3
A5: =IFERROR(INDEX('Raw Data'!$E$2:$E$50000,MATCH(2,'Raw Data'!$U$2:$U$50000,0)),"") -> RACHAYU | B5: =IF($A5="","",COUNTIFS('Raw Data'!$E$2:$E$50000,$A5)) -> 175 | C5: =IF($A5="","",SUMIFS('Raw Data'!$I$2:$I$50000,'Raw Data'!$E$2:$E$50000,$A5)) -> 4401000 | D5: =IF($A5="","",RANK($C5,$C$4:$C$11)+COUNTIF($C$4:C5,$C5)-1) -> 2
A6: =IFERROR(INDEX('Raw Data'!$E$2:$E$50000,MATCH(3,'Raw Data'!$U$2:$U$50000,0)),"") -> NAFARA | B6: =IF($A6="","",COUNTIFS('Raw Data'!$E$2:$E$50000,$A6)) -> 107 | C6: =IF($A6="","",SUMIFS('Raw Data'!$I$2:$I$50000,'Raw Data'!$E$2:$E$50000,$A6)) -> 2922000 | D6: =IF($A6="","",RANK($C6,$C$4:$C$11)+COUNTIF($C$4:C6,$C6)-1) -> 4
A7: =IFERROR(INDEX('Raw Data'!$E$2:$E$50000,MATCH(4,'Raw Data'!$U$2:$U$50000,0)),"") -> FATAPE | B7: =IF($A7="","",COUNTIFS('Raw Data'!$E$2:$E$50000,$A7)) -> 229 | C7: =IF($A7="","",SUMIFS('Raw Data'!$I$2:$I$50000,'Raw Data'!$E$2:$E$50000,$A7)) -> 8681000 | D7: =IF($A7="","",RANK($C7,$C$4:$C$11)+COUNTIF($C$4:C7,$C7)-1) -> 1
A8: =IFERROR(INDEX('Raw Data'!$E$2:$E$50000,MATCH(5,'Raw Data'!$U$2:$U$50000,0)),"") | B8: =IF($A8="","",COUNTIFS('Raw Data'!$E$2:$E$50000,$A8)) | C8: =IF($A8="","",SUMIFS('Raw Data'!$I$2:$I$50000,'Raw Data'!$E$2:$E$50000,$A8)) | D8: =IF($A8="","",RANK($C8,$C$4:$C$11)+COUNTIF($C$4:C8,$C8)-1)
A9: =IFERROR(INDEX('Raw Data'!$E$2:$E$50000,MATCH(6,'Raw Data'!$U$2:$U$50000,0)),"") | B9: =IF($A9="","",COUNTIFS('Raw Data'!$E$2:$E$50000,$A9)) | C9: =IF($A9="","",SUMIFS('Raw Data'!$I$2:$I$50000,'Raw Data'!$E$2:$E$50000,$A9)) | D9: =IF($A9="","",RANK($C9,$C$4:$C$11)+COUNTIF($C$4:C9,$C9)-1)
A10: =IFERROR(INDEX('Raw Data'!$E$2:$E$50000,MATCH(7,'Raw Data'!$U$2:$U$50000,0)),"") | B10: =IF($A10="","",COUNTIFS('Raw Data'!$E$2:$E$50000,$A10)) | C10: =IF($A10="","",SUMIFS('Raw Data'!$I$2:$I$50000,'Raw Data'!$E$2:$E$50000,$A10)) | D10: =IF($A10="","",RANK($C10,$C$4:$C$11)+COUNTIF($C$4:C10,$C10)-1)
A11: =IFERROR(INDEX('Raw Data'!$E$2:$E$50000,MATCH(8,'Raw Data'!$U$2:$U$50000,0)),"") | B11: =IF($A11="","",COUNTIFS('Raw Data'!$E$2:$E$50000,$A11)) | C11: =IF($A11="","",SUMIFS('Raw Data'!$I$2:$I$50000,'Raw Data'!$E$2:$E$50000,$A11)) | D11: =IF($A11="","",RANK($C11,$C$4:$C$11)+COUNTIF($C$4:C11,$C11)-1)

Sheet Rekap Service
A1: 🚚 REKAP PER LAYANAN
A3: Services | B3: Total_Transaksi | C3: Total_Pendapatan
A4: CTC05 | B4: =COUNTIFS('Raw Data'!$K$2:$K$50000,A4) -> 3 | C4: =SUMIFS('Raw Data'!$I$2:$I$50000,'Raw Data'!$K$2:$K$50000,A4) -> 16500
A5: CTC23 | B5: =COUNTIFS('Raw Data'!$K$2:$K$50000,A5) -> 8 | C5: =SUMIFS('Raw Data'!$I$2:$I$50000,'Raw Data'!$K$2:$K$50000,A5) -> 112000
A6: CTCJTR5_23 | B6: =COUNTIFS('Raw Data'!$K$2:$K$50000,A6) -> 1 | C6: =SUMIFS('Raw Data'!$I$2:$I$50000,'Raw Data'!$K$2:$K$50000,A6) -> 84000
A7: JTR23 | B7: =COUNTIFS('Raw Data'!$K$2:$K$50000,A7) -> 0 | C7: =SUMIFS('Raw Data'!$I$2:$I$50000,'Raw Data'!$K$2:$K$50000,A7) -> 0
A8: JTR5_23 | B8: =COUNTIFS('Raw Data'!$K$2:$K$50000,A8) -> 35 | C8: =SUMIFS('Raw Data'!$I$2:$I$50000,'Raw Data'!$K$2:$K$50000,A8) -> 4834000
A9: REG05 | B9: =COUNTIFS('Raw Data'!$K$2:$K$50000,A9) -> 87 | C9: =SUMIFS('Raw Data'!$I$2:$I$50000,'Raw Data'!$K$2:$K$50000,A9) -> 1596500
A10: REG23 | B10: =COUNTIFS('Raw Data'!$K$2:$K$50000,A10) -> 528 | C10: =SUMIFS('Raw Data'!$I$2:$I$50000,'Raw Data'!$K$2:$K$50000,A10) -> 12705000
A11: YES23 | B11: =COUNTIFS('Raw Data'!$K$2:$K$50000,A11) -> 28 | C11: =SUMIFS('Raw Data'!$I$2:$I$50000,'Raw Data'!$K$2:$K$50000,A11) -> 526000

Sheet Rekap Marketplace
A1: 🛒 REKAP PER MARKETPLACE
A4: Marketplace | B4: Total_Transaksi | C4: Total_Pendapatan
A5: SHOPEE | B5: =COUNTIFS('Raw Data'!$X$2:$X$50000,A5) -> 650 | C5: =SUMIFS('Raw Data'!$I$2:$I$50000,'Raw Data'!$X$2:$X$50000,A5) -> 19108000
A6: TOKOPEDIA | B6: =COUNTIFS('Raw Data'!$X$2:$X$50000,A6) -> 25 | C6: =SUMIFS('Raw Data'!$I$2:$I$50000,'Raw Data'!$X$2:$X$50000,A6) -> 541000
A7: LASTANA EXPRESS | B7: =COUNTIFS('Raw Data'!$X$2:$X$50000,A7) -> 1 | C7: =SUMIFS('Raw Data'!$I$2:$I$50000,'Raw Data'!$X$2:$X$50000,A7) -> 12000
A8: FASHION MARKETPLACE | B8: =COUNTIFS('Raw Data'!$X$2:$X$50000,A8) -> 3 | C8: =SUMIFS('Raw Data'!$I$2:$I$50000,'Raw Data'!$X$2:$X$50000,A8) -> 30000
A9: GLOBAL DIGITAL NIAGA | B9: =COUNTIFS('Raw Data'!$X$2:$X$50000,A9) -> 3 | C9: =SUMIFS('Raw Data'!$I$2:$I$50000,'Raw Data'!$X$2:$X$50000,A9) -> 60000
A10: TOKGISTIC | B10: =COUNTIFS('Raw Data'!$X$2:$X$50000,A10) -> 7 | C10: =SUMIFS('Raw Data'!$I$2:$I$50000,'Raw Data'!$X$2:$X$50000,A10) -> 111000
A11: TOCO RAMAI DIGITAL | B11: =COUNTIFS('Raw Data'!$X$2:$X$50000,A11) -> 1 | C11: =SUMIFS('Raw Data'!$I$2:$I$50000,'Raw Data'!$X$2:$X$50000,A11) -> 12000

Sheet _Cust_Helper
A1: Slot | B1: Cust_Id | C1: Cust_Name | D1: Total_Transaksi | E1: Total_Pendapatan | F1: Rank_Pendapatan | G1: Rank_Order
A2: 1 | B2: =IFERROR(INDEX('Raw Data'!$R$2:$R$50000,MATCH(1,'Raw Data'!$W$2:$W$50000,0)),"") -> Ulfiyani | C2: =IF($B2="","",$B2) -> Ulfiyani | D2: =IF($B2="","",COUNTIFS('Raw Data'!$R$2:$R$50000,$B2)) -> 2 | E2: =IF($B2="","",SUMIFS('Raw Data'!$I$2:$I$50000,'Raw Data'!$R$2:$R$50000,$B2)) -> 24000 | F2: =IF($B2="","",RANK($E2,$E$2:$E$1501)+COUNTIF($E$2:E2,$E2)-1) -> 116 | G2: =IF($B2="","",RANK($D2,$D$2:$D$1501)+COUNTIF($D$2:D2,$D2)-1) -> 52
A3: 2 | B3: =IFERROR(INDEX('Raw Data'!$R$2:$R$50000,MATCH(2,'Raw Data'!$W$2:$W$50000,0)),"") -> Maryani Yani/ mitra pompa | C3: =IF($B3="","",$B3) -> Maryani Yani/ mitra pompa | D3: =IF($B3="","",COUNTIFS('Raw Data'!$R$2:$R$50000,$B3)) -> 20 | E3: =IF($B3="","",SUMIFS('Raw Data'!$I$2:$I$50000,'Raw Data'!$R$2:$R$50000,$B3)) -> 605000 | F3: =IF($B3="","",RANK($E3,$E$2:$E$1501)+COUNTIF($E$2:E3,$E3)-1) -> 5 | G3: =IF($B3="","",RANK($D3,$D$2:$D$1501)+COUNTIF($D$2:D3,$D3)-1) -> 7
A4: 3 | B4: =IFERROR(INDEX('Raw Data'!$R$2:$R$50000,MATCH(3,'Raw Data'!$W$2:$W$50000,0)),"") -> Nadya Rameyza Elya | C4: =IF($B4="","",$B4) -> Nadya Rameyza Elya | D4: =IF($B4="","",COUNTIFS('Raw Data'!$R$2:$R$50000,$B4)) -> 7 | E4: =IF($B4="","",SUMIFS('Raw Data'!$I$2:$I$50000,'Raw Data'!$R$2:$R$50000,$B4)) -> 79000 | F4: =IF($B4="","",RANK($E4,$E$2:$E$1501)+COUNTIF($E$2:E4,$E4)-1) -> 46 | G4: =IF($B4="","",RANK($D4,$D$2:$D$1501)+COUNTIF($D$2:D4,$D4)-1) -> 15
A5: 4 | B5: =IFERROR(INDEX('Raw Data'!$R$2:$R$50000,MATCH(4,'Raw Data'!$W$2:$W$50000,0)),"") -> Nuraya Active | C5: =IF($B5="","",$B5) -> Nuraya Active | D5: =IF($B5="","",COUNTIFS('Raw Data'!$R$2:$R$50000,$B5)) -> 1 | E5: =IF($B5="","",SUMIFS('Raw Data'!$I$2:$I$50000,'Raw Data'!$R$2:$R$50000,$B5)) -> 29000 | F5: =IF($B5="","",RANK($E5,$E$2:$E$1501)+COUNTIF($E$2:E5,$E5)-1) -> 107 | G5: =IF($B5="","",RANK($D5,$D$2:$D$1501)+COUNTIF($D$2:D5,$D5)-1) -> 88
A6: 5 | B6: =IFERROR(INDEX('Raw Data'!$R$2:$R$50000,MATCH(5,'Raw Data'!$W$2:$W$50000,0)),"") -> Dani Hamdani (Yasashi Japan) | C6: =IF($B6="","",$B6) -> Dani Hamdani (Yasashi Japan) | D6: =IF($B6="","",COUNTIFS('Raw Data'!$R$2:$R$50000,$B6)) -> 34 | E6: =IF($B6="","",SUMIFS('Raw Data'!$I$2:$I$50000,'Raw Data'!$R$2:$R$50000,$B6)) -> 521500 | F6: =IF($B6="","",RANK($E6,$E$2:$E$1501)+COUNTIF($E$2:E6,$E6)-1) -> 6 | G6: =IF($B6="","",RANK($D6,$D$2:$D$1501)+COUNTIF($D$2:D6,$D6)-1) -> 2
A7: 6 | B7: =IFERROR(INDEX('Raw Data'!$R$2:$R$50000,MATCH(6,'Raw Data'!$W$2:$W$50000,0)),"") -> Michael L. | C7: =IF($B7="","",$B7) -> Michael L. | D7: =IF($B7="","",COUNTIFS('Raw Data'!$R$2:$R$50000,$B7)) -> 29 | E7: =IF($B7="","",SUMIFS('Raw Data'!$I$2:$I$50000,'Raw Data'!$R$2:$R$50000,$B7)) -> 825000 | F7: =IF($B7="","",RANK($E7,$E$2:$E$1501)+COUNTIF($E$2:E7,$E7)-1) -> 3 | G7: =IF($B7="","",RANK($D7,$D$2:$D$1501)+COUNTIF($D$2:D7,$D7)-1) -> 3
A8: 7 | B8: =IFERROR(INDEX('Raw Data'!$R$2:$R$50000,MATCH(7,'Raw Data'!$W$2:$W$50000,0)),"") -> MICHAEL LONDA | C8: =IF($B8="","",$B8) -> MICHAEL LONDA | D8: =IF($B8="","",COUNTIFS('Raw Data'!$R$2:$R$50000,$B8)) -> 1 | E8: =IF($B8="","",SUMIFS('Raw Data'!$I$2:$I$50000,'Raw Data'!$R$2:$R$50000,$B8)) -> 12000 | F8: =IF($B8="","",RANK($E8,$E$2:$E$1501)+COUNTIF($E$2:E8,$E8)-1) -> 157 | G8: =IF($B8="","",RANK($D8,$D$2:$D$1501)+COUNTIF($D$2:D8,$D8)-1) -> 89
A9: 8 | B9: =IFERROR(INDEX('Raw Data'!$R$2:$R$50000,MATCH(8,'Raw Data'!$W$2:$W$50000,0)),"") -> Yasashi Japan Shop | C9: =IF($B9="","",$B9) -> Yasashi Japan Shop | D9: =IF($B9="","",COUNTIFS('Raw Data'!$R$2:$R$50000,$B9)) -> 6 | E9: =IF($B9="","",SUMIFS('Raw Data'!$I$2:$I$50000,'Raw Data'!$R$2:$R$50000,$B9)) -> 105000 | F9: =IF($B9="","",RANK($E9,$E$2:$E$1501)+COUNTIF($E$2:E9,$E9)-1) -> 35 | G9: =IF($B9="","",RANK($D9,$D$2:$D$1501)+COUNTIF($D$2:D9,$D9)-1) -> 19
A10: 9 | B10: =IFERROR(INDEX('Raw Data'!$R$2:$R$50000,MATCH(9,'Raw Data'!$W$2:$W$50000,0)),"") -> DEDE SULAEMAN SULAEMAN | C10: =IF($B10="","",$B10) -> DEDE SULAEMAN SULAEMAN | D10: =IF($B10="","",COUNTIFS('Raw Data'!$R$2:$R$50000,$B10)) -> 1 | E10: =IF($B10="","",SUMIFS('Raw Data'!$I$2:$I$50000,'Raw Data'!$R$2:$R$50000,$B10)) -> 10000 | F10: =IF($B10="","",RANK($E10,$E$2:$E$1501)+COUNTIF($E$2:E10,$E10)-1) -> 218 | G10: =IF($B10="","",RANK($D10,$D$2:$D$1501)+COUNTIF($D$2:D10,$D10)-1) -> 90
A11: 10 | B11: =IFERROR(INDEX('Raw Data'!$R$2:$R$50000,MATCH(10,'Raw Data'!$W$2:$W$50000,0)),"") -> Angel Cos | C11: =IF($B11="","",$B11) -> Angel Cos | D11: =IF($B11="","",COUNTIFS('Raw Data'!$R$2:$R$50000,$B11)) -> 1 | E11: =IF($B11="","",SUMIFS('Raw Data'!$I$2:$I$50000,'Raw Data'!$R$2:$R$50000,$B11)) -> 58000 | F11: =IF($B11="","",RANK($E11,$E$2:$E$1501)+COUNTIF($E$2:E11,$E11)-1) -> 61 | G11: =IF($B11="","",RANK($D11,$D$2:$D$1501)+COUNTIF($D$2:D11,$D11)-1) -> 91
A12: 11 | B12: =IFERROR(INDEX('Raw Data'!$R$2:$R$50000,MATCH(11,'Raw Data'!$W$2:$W$50000,0)),"") -> BLUNDER_SW | C12: =IF($B12="","",$B12) -> BLUNDER_SW | D12: =IF($B12="","",COUNTIFS('Raw Data'!$R$2:$R$50000,$B12)) -> 2 | E12: =IF($B12="","",SUMIFS('Raw Data'!$I$2:$I$50000,'Raw Data'!$R$2:$R$50000,$B12)) -> 36000 | F12: =IF($B12="","",RANK($E12,$E$2:$E$1501)+COUNTIF($E$2:E12,$E12)-1) -> 90 | G12: =IF($B12="","",RANK($D12,$D$2:$D$1501)+COUNTIF($D$2:D12,$D12)-1) -> 53
A13: 12 | B13: =IFERROR(INDEX('Raw Data'!$R$2:$R$50000,MATCH(12,'Raw Data'!$W$2:$W$50000,0)),"") -> FIRDAYANI | C13: =IF($B13="","",$B13) -> FIRDAYANI | D13: =IF($B13="","",COUNTIFS('Raw Data'!$R$2:$R$50000,$B13)) -> 1 | E13: =IF($B13="","",SUMIFS('Raw Data'!$I$2:$I$50000,'Raw Data'!$R$2:$R$50000,$B13)) -> 78000 | F13: =IF($B13="","",RANK($E13,$E$2:$E$1501)+COUNTIF($E$2:E13,$E13)-1) -> 47 | G13: =IF($B13="","",RANK($D13,$D$2:$D$1501)+COUNTIF($D$2:D13,$D13)-1) -> 92
A14: 13 | B14: =IFERROR(INDEX('Raw Data'!$R$2:$R$50000,MATCH(13,'Raw Data'!$W$2:$W$50000,0)),"") -> Ferdian | C14: =IF($B14="","",$B14) -> Ferdian | D14: =IF($B14="","",COUNTIFS('Raw Data'!$R$2:$R$50000,$B14)) -> 4 | E14: =IF($B14="","",SUMIFS('Raw Data'!$I$2:$I$50000,'Raw Data'!$R$2:$R$50000,$B14)) -> 48000 | F14: =IF($B14="","",RANK($E14,$E$2:$E$1501)+COUNTIF($E$2:E14,$E14)-1) -> 76 | G14: =IF($B14="","",RANK($D14,$D$2:$D$1501)+COUNTIF($D$2:D14,$D14)-1) -> 29
A15: 14 | B15: =IFERROR(INDEX('Raw Data'!$R$2:$R$50000,MATCH(14,'Raw Data'!$W$2:$W$50000,0)),"") -> Faza | C15: =IF($B15="","",$B15) -> Faza | D15: =IF($B15="","",COUNTIFS('Raw Data'!$R$2:$R$50000,$B15)) -> 3 | E15: =IF($B15="","",SUMIFS('Raw Data'!$I$2:$I$50000,'Raw Data'!$R$2:$R$50000,$B15)) -> 56000 | F15: =IF($B15="","",RANK($E15,$E$2:$E$1501)+COUNTIF($E$2:E15,$E15)-1) -> 64 | G15: =IF($B15="","",RANK($D15,$D$2:$D$1501)+COUNTIF($D$2:D15,$D15)-1) -> 39
A16: 15 | B16: =IFERROR(INDEX('Raw Data'!$R$2:$R$50000,MATCH(15,'Raw Data'!$W$2:$W$50000,0)),"") -> Rini Ayu Alwiyah | C16: =IF($B16="","",$B16) -> Rini Ayu Alwiyah | D16: =IF($B16="","",COUNTIFS('Raw Data'!$R$2:$R$50000,$B16)) -> 4 | E16: =IF($B16="","",SUMIFS('Raw Data'!$I$2:$I$50000,'Raw Data'!$R$2:$R$50000,$B16)) -> 50000 | F16: =IF($B16="","",RANK($E16,$E$2:$E$1501)+COUNTIF($E$2:E16,$E16)-1) -> 72 | G16: =IF($B16="","",RANK($D16,$D$2:$D$1501)+COUNTIF($D$2:D16,$D16)-1) -> 30
A17: 16 | B17: =IFERROR(INDEX('Raw Data'!$R$2:$R$50000,MATCH(16,'Raw Data'!$W$2:$W$50000,0)),"") -> Dela Natalia Saputra | C17: =IF($B17="","",$B17) -> Dela Natalia Saputra | D17: =IF($B17="","",COUNTIFS('Raw Data'!$R$2:$R$50000,$B17)) -> 25 | E17: =IF($B17="","",SUMIFS('Raw Data'!$I$2:$I$50000,'Raw Data'!$R$2:$R$50000,$B17)) -> 492000 | F17: =IF($B17="","",RANK($E17,$E$2:$E$1501)+COUNTIF($E$2:E17,$E17)-1) -> 9 | G17: =IF($B17="","",RANK($D17,$D$2:$D$1501)+COUNTIF($D$2:D17,$D17)-1) -> 4
A18: 17 | B18: =IFERROR(INDEX('Raw Data'!$R$2:$R$50000,MATCH(17,'Raw Data'!$W$2:$W$50000,0)),"") -> ALDI APRIL BAGUS TANOTO | C18: =IF($B18="","",$B18) -> ALDI APRIL BAGUS TANOTO | D18: =IF($B18="","",COUNTIFS('Raw Data'!$R$2:$R$50000,$B18)) -> 3 | E18: =IF($B18="","",SUMIFS('Raw Data'!$I$2:$I$50000,'Raw Data'!$R$2:$R$50000,$B18)) -> 117000 | F18: =IF($B18="","",RANK($E18,$E$2:$E$1501)+COUNTIF($E$2:E18,$E18)-1) -> 32 | G18: =IF($B18="","",RANK($D18,$D$2:$D$1501)+COUNTIF($D$2:D18,$D18)-1) -> 40
A19: 18 | B19: =IFERROR(INDEX('Raw Data'!$R$2:$R$50000,MATCH(18,'Raw Data'!$W$2:$W$50000,0)),"") -> Ari Winda | C19: =IF($B19="","",$B19) -> Ari Winda | D19: =IF($B19="","",COUNTIFS('Raw Data'!$R$2:$R$50000,$B19)) -> 15 | E19: =IF($B19="","",SUMIFS('Raw Data'!$I$2:$I$50000,'Raw Data'!$R$2:$R$50000,$B19)) -> 311000 | F19: =IF($B19="","",RANK($E19,$E$2:$E$1501)+COUNTIF($E$2:E19,$E19)-1) -> 14 | G19: =IF($B19="","",RANK($D19,$D$2:$D$1501)+COUNTIF($D$2:D19,$D19)-1) -> 12
A20: 19 | B20: =IFERROR(INDEX('Raw Data'!$R$2:$R$50000,MATCH(19,'Raw Data'!$W$2:$W$50000,0)),"") -> DEVIRAMA | C20: =IF($B20="","",$B20) -> DEVIRAMA | D20: =IF($B20="","",COUNTIFS('Raw Data'!$R$2:$R$50000,$B20)) -> 1 | E20: =IF($B20="","",SUMIFS('Raw Data'!$I$2:$I$50000,'Raw Data'!$R$2:$R$50000,$B20)) -> 58500 | F20: =IF($B20="","",RANK($E20,$E$2:$E$1501)+COUNTIF($E$2:E20,$E20)-1) -> 59 | G20: =IF($B20="","",RANK($D20,$D$2:$D$1501)+COUNTIF($D$2:D20,$D20)-1) -> 93
A21: 20 | B21: =IFERROR(INDEX('Raw Data'!$R$2:$R$50000,MATCH(20,'Raw Data'!$W$2:$W$50000,0)),"") -> Syifa zakiyah | C21: =IF($B21="","",$B21) -> Syifa zakiyah | D21: =IF($B21="","",COUNTIFS('Raw Data'!$R$2:$R$50000,$B21)) -> 1 | E21: =IF($B21="","",SUMIFS('Raw Data'!$I$2:$I$50000,'Raw Data'!$R$2:$R$50000,$B21)) -> 12000 | F21: =IF($B21="","",RANK($E21,$E$2:$E$1501)+COUNTIF($E$2:E21,$E21)-1) -> 158 | G21: =IF($B21="","",RANK($D21,$D$2:$D$1501)+COUNTIF($D$2:D21,$D21)-1) -> 94
A22: 21 | B22: =IFERROR(INDEX('Raw Data'!$R$2:$R$50000,MATCH(21,'Raw Data'!$W$2:$W$50000,0)),"") -> Toko Sepeda UWO2 | C22: =IF($B22="","",$B22) -> Toko Sepeda UWO2 | D22: =IF($B22="","",COUNTIFS('Raw Data'!$R$2:$R$50000,$B22)) -> 7 | E22: =IF($B22="","",SUMIFS('Raw Data'!$I$2:$I$50000,'Raw Data'!$R$2:$R$50000,$B22)) -> 3247000 | F22: =IF($B22="","",RANK($E22,$E$2:$E$1501)+COUNTIF($E$2:E22,$E22)-1) -> 1 | G22: =IF($B22="","",RANK($D22,$D$2:$D$1501)+COUNTIF($D$2:D22,$D22)-1) -> 16
A23: 22 | B23: =IFERROR(INDEX('Raw Data'!$R$2:$R$50000,MATCH(22,'Raw Data'!$W$2:$W$50000,0)),"") -> Nature By GLife | C23: =IF($B23="","",$B23) -> Nature By GLife | D23: =IF($B23="","",COUNTIFS('Raw Data'!$R$2:$R$50000,$B23)) -> 6 | E23: =IF($B23="","",SUMIFS('Raw Data'!$I$2:$I$50000,'Raw Data'!$R$2:$R$50000,$B23)) -> 88000 | F23: =IF($B23="","",RANK($E23,$E$2:$E$1501)+COUNTIF($E$2:E23,$E23)-1) -> 43 | G23: =IF($B23="","",RANK($D23,$D$2:$D$1501)+COUNTIF($D$2:D23,$D23)-1) -> 20
A24: 23 | B24: =IFERROR(INDEX('Raw Data'!$R$2:$R$50000,MATCH(23,'Raw Data'!$W$2:$W$50000,0)),"") -> ratna (gii) | C24: =IF($B24="","",$B24) -> ratna (gii) | D24: =IF($B24="","",COUNTIFS('Raw Data'!$R$2:$R$50000,$B24)) -> 25 | E24: =IF($B24="","",SUMIFS('Raw Data'!$I$2:$I$50000,'Raw Data'!$R$2:$R$50000,$B24)) -> 441500 | F24: =IF($B24="","",RANK($E24,$E$2:$E$1501)+COUNTIF($E$2:E24,$E24)-1) -> 11 | G24: =IF($B24="","",RANK($D24,$D$2:$D$1501)+COUNTIF($D$2:D24,$D24)-1) -> 5
A25: 24 | B25: =IFERROR(INDEX('Raw Data'!$R$2:$R$50000,MATCH(24,'Raw Data'!$W$2:$W$50000,0)),"") -> Faradithya Putri Lakcyta | C25: =IF($B25="","",$B25) -> Faradithya Putri Lakcyta | D25: =IF($B25="","",COUNTIFS('Raw Data'!$R$2:$R$50000,$B25)) -> 67 | E25: =IF($B25="","",SUMIFS('Raw Data'!$I$2:$I$50000,'Raw Data'!$R$2:$R$50000,$B25)) -> 1301000 | F25: =IF($B25="","",RANK($E25,$E$2:$E$1501)+COUNTIF($E$2:E25,$E25)-1) -> 2 | G25: =IF($B25="","",RANK($D25,$D$2:$D$1501)+COUNTIF($D$2:D25,$D25)-1) -> 1
A26: 25 | B26: =IFERROR(INDEX('Raw Data'!$R$2:$R$50000,MATCH(25,'Raw Data'!$W$2:$W$50000,0)),"") -> SJM Paper & Sticker | C26: =IF($B26="","",$B26) -> SJM Paper & Sticker | D26: =IF($B26="","",COUNTIFS('Raw Data'!$R$2:$R$50000,$B26)) -> 16 | E26: =IF($B26="","",SUMIFS('Raw Data'!$I$2:$I$50000,'Raw Data'!$R$2:$R$50000,$B26)) -> 504000 | F26: =IF($B26="","",RANK($E26,$E$2:$E$1501)+COUNTIF($E$2:E26,$E26)-1) -> 8 | G26: =IF($B26="","",RANK($D26,$D$2:$D$1501)+COUNTIF($D$2:D26,$D26)-1) -> 9
A27: 26 | B27: =IFERROR(INDEX('Raw Data'!$R$2:$R$50000,MATCH(26,'Raw Data'!$W$2:$W$50000,0)),"") -> Klinik ESHA Skin Center | C27: =IF($B27="","",$B27) -> Klinik ESHA Skin Center | D27: =IF($B27="","",COUNTIFS('Raw Data'!$R$2:$R$50000,$B27)) -> 16 | E27: =IF($B27="","",SUMIFS('Raw Data'!$I$2:$I$50000,'Raw Data'!$R$2:$R$50000,$B27)) -> 340000 | F27: =IF($B27="","",RANK($E27,$E$2:$E$1501)+COUNTIF($E$2:E27,$E27)-1) -> 13 | G27: =IF($B27="","",RANK($D27,$D$2:$D$1501)+COUNTIF($D$2:D27,$D27)-1) -> 10
A28: 27 | B28: =IFERROR(INDEX('Raw Data'!$R$2:$R$50000,MATCH(27,'Raw Data'!$W$2:$W$50000,0)),"") -> Pacificdental_group | C28: =IF($B28="","",$B28) -> Pacificdental_group | D28: =IF($B28="","",COUNTIFS('Raw Data'!$R$2:$R$50000,$B28)) -> 21 | E28: =IF($B28="","",SUMIFS('Raw Data'!$I$2:$I$50000,'Raw Data'!$R$2:$R$50000,$B28)) -> 613500 | F28: =IF($B28="","",RANK($E28,$E$2:$E$1501)+COUNTIF($E$2:E28,$E28)-1) -> 4 | G28: =IF($B28="","",RANK($D28,$D$2:$D$1501)+COUNTIF($D$2:D28,$D28)-1) -> 6
A29: 28 | B29: =IFERROR(INDEX('Raw Data'!$R$2:$R$50000,MATCH(28,'Raw Data'!$W$2:$W$50000,0)),"") -> Zefanya Andrian Wijaya | C29: =IF($B29="","",$B29) -> Zefanya Andrian Wijaya | D29: =IF($B29="","",COUNTIFS('Raw Data'!$R$2:$R$50000,$B29)) -> 1 | E29: =IF($B29="","",SUMIFS('Raw Data'!$I$2:$I$50000,'Raw Data'!$R$2:$R$50000,$B29)) -> 24000 | F29: =IF($B29="","",RANK($E29,$E$2:$E$1501)+COUNTIF($E$2:E29,$E29)-1) -> 117 | G29: =IF($B29="","",RANK($D29,$D$2:$D$1501)+COUNTIF($D$2:D29,$D29)-1) -> 95
A30: 29 | B30: =IFERROR(INDEX('Raw Data'!$R$2:$R$50000,MATCH(29,'Raw Data'!$W$2:$W$50000,0)),"") -> Albert Gunawan Wiratma | C30: =IF($B30="","",$B30) -> Albert Gunawan Wiratma | D30: =IF($B30="","",COUNTIFS('Raw Data'!$R$2:$R$50000,$B30)) -> 6 | E30: =IF($B30="","",SUMIFS('Raw Data'!$I$2:$I$50000,'Raw Data'!$R$2:$R$50000,$B30)) -> 90000 | F30: =IF($B30="","",RANK($E30,$E$2:$E$1501)+COUNTIF($E$2:E30,$E30)-1) -> 42 | G30: =IF($B30="","",RANK($D30,$D$2:$D$1501)+COUNTIF($D$2:D30,$D30)-1) -> 21
A31: 30 | B31: =IFERROR(INDEX('Raw Data'!$R$2:$R$50000,MATCH(30,'Raw Data'!$W$2:$W$50000,0)),"") -> Widia Karlina | C31: =IF($B31="","",$B31) -> Widia Karlina | D31: =IF($B31="","",COUNTIFS('Raw Data'!$R$2:$R$50000,$B31)) -> 2 | E31: =IF($B31="","",SUMIFS('Raw Data'!$I$2:$I$50000,'Raw Data'!$R$2:$R$50000,$B31)) -> 46000 | F31: =IF($B31="","",RANK($E31,$E$2:$E$1501)+COUNTIF($E$2:E31,$E31)-1) -> 82 | G31: =IF($B31="","",RANK($D31,$D$2:$D$1501)+COUNTIF($D$2:D31,$D31)-1) -> 54
A32: 31 | B32: =IFERROR(INDEX('Raw Data'!$R$2:$R$50000,MATCH(31,'Raw Data'!$W$2:$W$50000,0)),"") -> saila | C32: =IF($B32="","",$B32) -> saila | D32: =IF($B32="","",COUNTIFS('Raw Data'!$R$2:$R$50000,$B32)) -> 1 | E32: =IF($B32="","",SUMIFS('Raw Data'!$I$2:$I$50000,'Raw Data'!$R$2:$R$50000,$B32)) -> 12000 | F32: =IF($B32="","",RANK($E32,$E$2:$E$1501)+COUNTIF($E$2:E32,$E32)-1) -> 159 | G32: =IF($B32="","",RANK($D32,$D$2:$D$1501)+COUNTIF($D$2:D32,$D32)-1) -> 96
A33: 32 | B33: =IFERROR(INDEX('Raw Data'!$R$2:$R$50000,MATCH(32,'Raw Data'!$W$2:$W$50000,0)),"") -> Rosadi | C33: =IF($B33="","",$B33) -> Rosadi | D33: =IF($B33="","",COUNTIFS('Raw Data'!$R$2:$R$50000,$B33)) -> 3 | E33: =IF($B33="","",SUMIFS('Raw Data'!$I$2:$I$50000,'Raw Data'!$R$2:$R$50000,$B33)) -> 68000 | F33: =IF($B33="","",RANK($E33,$E$2:$E$1501)+COUNTIF($E$2:E33,$E33)-1) -> 54 | G33: =IF($B33="","",RANK($D33,$D$2:$D$1501)+COUNTIF($D$2:D33,$D33)-1) -> 41
A34: 33 | B34: =IFERROR(INDEX('Raw Data'!$R$2:$R$50000,MATCH(33,'Raw Data'!$W$2:$W$50000,0)),"") -> Sandy | C34: =IF($B34="","",$B34) -> Sandy | D34: =IF($B34="","",COUNTIFS('Raw Data'!$R$2:$R$50000,$B34)) -> 4 | E34: =IF($B34="","",SUMIFS('Raw Data'!$I$2:$I$50000,'Raw Data'!$R$2:$R$50000,$B34)) -> 96000 | F34: =IF($B34="","",RANK($E34,$E$2:$E$1501)+COUNTIF($E$2:E34,$E34)-1) -> 38 | G34: =IF($B34="","",RANK($D34,$D$2:$D$1501)+COUNTIF($D$2:D34,$D34)-1) -> 31
A35: 34 | B35: =IFERROR(INDEX('Raw Data'!$R$2:$R$50000,MATCH(34,'Raw Data'!$W$2:$W$50000,0)),"") -> OLVeshop | C35: =IF($B35="","",$B35) -> OLVeshop | D35: =IF($B35="","",COUNTIFS('Raw Data'!$R$2:$R$50000,$B35)) -> 1 | E35: =IF($B35="","",SUMIFS('Raw Data'!$I$2:$I$50000,'Raw Data'!$R$2:$R$50000,$B35)) -> 25000 | F35: =IF($B35="","",RANK($E35,$E$2:$E$1501)+COUNTIF($E$2:E35,$E35)-1) -> 115 | G35: =IF($B35="","",RANK($D35,$D$2:$D$1501)+COUNTIF($D$2:D35,$D35)-1) -> 97
A36: 35 | B36: =IFERROR(INDEX('Raw Data'!$R$2:$R$50000,MATCH(35,'Raw Data'!$W$2:$W$50000,0)),"") -> Salsabila Nurulhilmiya | C36: =IF($B36="","",$B36) -> Salsabila Nurulhilmiya | D36: =IF($B36="","",COUNTIFS('Raw Data'!$R$2:$R$50000,$B36)) -> 1 | E36: =IF($B36="","",SUMIFS('Raw Data'!$I$2:$I$50000,'Raw Data'!$R$2:$R$50000,$B36)) -> 10000 | F36: =IF($B36="","",RANK($E36,$E$2:$E$1501)+COUNTIF($E$2:E36,$E36)-1) -> 219 | G36: =IF($B36="","",RANK($D36,$D$2:$D$1501)+COUNTIF($D$2:D36,$D36)-1) -> 98
A37: 36 | B37: =IFERROR(INDEX('Raw Data'!$R$2:$R$50000,MATCH(36,'Raw Data'!$W$2:$W$50000,0)),"") -> AGUNG LAKSONO | C37: =IF($B37="","",$B37) -> AGUNG LAKSONO | D37: =IF($B37="","",COUNTIFS('Raw Data'!$R$2:$R$50000,$B37)) -> 1 | E37: =IF($B37="","",SUMIFS('Raw Data'!$I$2:$I$50000,'Raw Data'!$R$2:$R$50000,$B37)) -> 12000 | F37: =IF($B37="","",RANK($E37,$E$2:$E$1501)+COUNTIF($E$2:E37,$E37)-1) -> 160 | G37: =IF($B37="","",RANK($D37,$D$2:$D$1501)+COUNTIF($D$2:D37,$D37)-1) -> 99
A38: 37 | B38: =IFERROR(INDEX('Raw Data'!$R$2:$R$50000,MATCH(37,'Raw Data'!$W$2:$W$50000,0)),"") -> DEDE MUTAKIN | C38: =IF($B38="","",$B38) -> DEDE MUTAKIN | D38: =IF($B38="","",COUNTIFS('Raw Data'!$R$2:$R$50000,$B38)) -> 2 | E38: =IF($B38="","",SUMIFS('Raw Data'!$I$2:$I$50000,'Raw Data'!$R$2:$R$50000,$B38)) -> 58500 | F38: =IF($B38="","",RANK($E38,$E$2:$E$1501)+COUNTIF($E$2:E38,$E38)-1) -> 60 | G38: =IF($B38="","",RANK($D38,$D$2:$D$1501)+COUNTIF($D$2:D38,$D38)-1) -> 55
A39: 38 | B39: =IFERROR(INDEX('Raw Data'!$R$2:$R$50000,MATCH(38,'Raw Data'!$W$2:$W$50000,0)),"") -> Ratu Maharani Kharty Kea | C39: =IF($B39="","",$B39) -> Ratu Maharani Kharty Kea | D39: =IF($B39="","",COUNTIFS('Raw Data'!$R$2:$R$50000,$B39)) -> 1 | E39: =IF($B39="","",SUMIFS('Raw Data'!$I$2:$I$50000,'Raw Data'!$R$2:$R$50000,$B39)) -> 12000 | F39: =IF($B39="","",RANK($E39,$E$2:$E$1501)+COUNTIF($E$2:E39,$E39)-1) -> 161 | G39: =IF($B39="","",RANK($D39,$D$2:$D$1501)+COUNTIF($D$2:D39,$D39)-1) -> 100
A40: 39 | B40: =IFERROR(INDEX('Raw Data'!$R$2:$R$50000,MATCH(39,'Raw Data'!$W$2:$W$50000,0)),"") -> Jalan Proklamasi No 6 RT6 Rw5 | C40: =IF($B40="","",$B40) -> Jalan Proklamasi No 6 RT6 Rw5 | D40: =IF($B40="","",COUNTIFS('Raw Data'!$R$2:$R$50000,$B40)) -> 16 | E40: =IF($B40="","",SUMIFS('Raw Data'!$I$2:$I$50000,'Raw Data'!$R$2:$R$50000,$B40)) -> 393500 | F40: =IF($B40="","",RANK($E40,$E$2:$E$1501)+COUNTIF($E$2:E40,$E40)-1) -> 12 | G40: =IF($B40="","",RANK($D40,$D$2:$D$1501)+COUNTIF($D$2:D40,$D40)-1) -> 11
...

Sheet Top Customer
A1: 🏆 TOP CUSTOMER
A2: ="Periode: "&TEXT(MAX('Raw Data'!$Q$2:$Q$50000),"MMMM YYYY")&"" -> Periode: July 2026
A4: 👤 TOTAL CUSTOMER | D4: CUSTOMER TERBESAR (PENDAPATAN)
A5: =COUNT(_Cust_Helper!$F$2:$F$1501) -> 226 | D5: =INDEX(_Cust_Helper!$C$2:$C$1501,MATCH(1,_Cust_Helper!$F$2:$F$1501,0))&" — Rp"&TEXT(INDEX(_Cust_Helper!$E$2:$E$1501,MATCH(1,_Cust_Helper!$F$2:$F$1501,0)),"#,##0") -> Toko Sepeda UWO2 — Rp3,247,000
A8: 📋 Top 10 Customer — Berdasarkan Total Pendapatan
A9: Rank | B9: Nama Customer | C9: Connote | D9: Revenue | E9: Rata-rata/Order
A10: 1 | B10: =IFERROR(INDEX(_Cust_Helper!$C$2:$C$1501,MATCH(1,_Cust_Helper!$F$2:$F$1501,0)),"") -> Toko Sepeda UWO2 | C10: =IF($B10="","",INDEX(_Cust_Helper!$D$2:$D$1501,MATCH(1,_Cust_Helper!$F$2:$F$1501,0))) -> 7 | D10: =IF($B10="","",INDEX(_Cust_Helper!$E$2:$E$1501,MATCH(1,_Cust_Helper!$F$2:$F$1501,0))) -> 3247000 | E10: =IF($B10="","",IF($C10=0,0,$D10/$C10)) -> 463857.14
A11: 2 | B11: =IFERROR(INDEX(_Cust_Helper!$C$2:$C$1501,MATCH(2,_Cust_Helper!$F$2:$F$1501,0)),"") -> Faradithya Putri Lakcyta | C11: =IF($B11="","",INDEX(_Cust_Helper!$D$2:$D$1501,MATCH(2,_Cust_Helper!$F$2:$F$1501,0))) -> 67 | D11: =IF($B11="","",INDEX(_Cust_Helper!$E$2:$E$1501,MATCH(2,_Cust_Helper!$F$2:$F$1501,0))) -> 1301000 | E11: =IF($B11="","",IF($C11=0,0,$D11/$C11)) -> 19417.91
A12: 3 | B12: =IFERROR(INDEX(_Cust_Helper!$C$2:$C$1501,MATCH(3,_Cust_Helper!$F$2:$F$1501,0)),"") -> Michael L. | C12: =IF($B12="","",INDEX(_Cust_Helper!$D$2:$D$1501,MATCH(3,_Cust_Helper!$F$2:$F$1501,0))) -> 29 | D12: =IF($B12="","",INDEX(_Cust_Helper!$E$2:$E$1501,MATCH(3,_Cust_Helper!$F$2:$F$1501,0))) -> 825000 | E12: =IF($B12="","",IF($C12=0,0,$D12/$C12)) -> 28448.276
A13: 4 | B13: =IFERROR(INDEX(_Cust_Helper!$C$2:$C$1501,MATCH(4,_Cust_Helper!$F$2:$F$1501,0)),"") -> Pacificdental_group | C13: =IF($B13="","",INDEX(_Cust_Helper!$D$2:$D$1501,MATCH(4,_Cust_Helper!$F$2:$F$1501,0))) -> 21 | D13: =IF($B13="","",INDEX(_Cust_Helper!$E$2:$E$1501,MATCH(4,_Cust_Helper!$F$2:$F$1501,0))) -> 613500 | E13: =IF($B13="","",IF($C13=0,0,$D13/$C13)) -> 29214.286
A14: 5 | B14: =IFERROR(INDEX(_Cust_Helper!$C$2:$C$1501,MATCH(5,_Cust_Helper!$F$2:$F$1501,0)),"") -> Maryani Yani/ mitra pompa | C14: =IF($B14="","",INDEX(_Cust_Helper!$D$2:$D$1501,MATCH(5,_Cust_Helper!$F$2:$F$1501,0))) -> 20 | D14: =IF($B14="","",INDEX(_Cust_Helper!$E$2:$E$1501,MATCH(5,_Cust_Helper!$F$2:$F$1501,0))) -> 605000 | E14: =IF($B14="","",IF($C14=0,0,$D14/$C14)) -> 30250
A15: 6 | B15: =IFERROR(INDEX(_Cust_Helper!$C$2:$C$1501,MATCH(6,_Cust_Helper!$F$2:$F$1501,0)),"") -> Dani Hamdani (Yasashi Japan) | C15: =IF($B15="","",INDEX(_Cust_Helper!$D$2:$D$1501,MATCH(6,_Cust_Helper!$F$2:$F$1501,0))) -> 34 | D15: =IF($B15="","",INDEX(_Cust_Helper!$E$2:$E$1501,MATCH(6,_Cust_Helper!$F$2:$F$1501,0))) -> 521500 | E15: =IF($B15="","",IF($C15=0,0,$D15/$C15)) -> 15338.235
A16: 7 | B16: =IFERROR(INDEX(_Cust_Helper!$C$2:$C$1501,MATCH(7,_Cust_Helper!$F$2:$F$1501,0)),"") -> Lunalita (Lutfiyatul Hanifah) | C16: =IF($B16="","",INDEX(_Cust_Helper!$D$2:$D$1501,MATCH(7,_Cust_Helper!$F$2:$F$1501,0))) -> 18 | D16: =IF($B16="","",INDEX(_Cust_Helper!$E$2:$E$1501,MATCH(7,_Cust_Helper!$F$2:$F$1501,0))) -> 521000 | E16: =IF($B16="","",IF($C16=0,0,$D16/$C16)) -> 28944.444
A17: 8 | B17: =IFERROR(INDEX(_Cust_Helper!$C$2:$C$1501,MATCH(8,_Cust_Helper!$F$2:$F$1501,0)),"") -> SJM Paper & Sticker | C17: =IF($B17="","",INDEX(_Cust_Helper!$D$2:$D$1501,MATCH(8,_Cust_Helper!$F$2:$F$1501,0))) -> 16 | D17: =IF($B17="","",INDEX(_Cust_Helper!$E$2:$E$1501,MATCH(8,_Cust_Helper!$F$2:$F$1501,0))) -> 504000 | E17: =IF($B17="","",IF($C17=0,0,$D17/$C17)) -> 31500
A18: 9 | B18: =IFERROR(INDEX(_Cust_Helper!$C$2:$C$1501,MATCH(9,_Cust_Helper!$F$2:$F$1501,0)),"") -> Dela Natalia Saputra | C18: =IF($B18="","",INDEX(_Cust_Helper!$D$2:$D$1501,MATCH(9,_Cust_Helper!$F$2:$F$1501,0))) -> 25 | D18: =IF($B18="","",INDEX(_Cust_Helper!$E$2:$E$1501,MATCH(9,_Cust_Helper!$F$2:$F$1501,0))) -> 492000 | E18: =IF($B18="","",IF($C18=0,0,$D18/$C18)) -> 19680
A19: 10 | B19: =IFERROR(INDEX(_Cust_Helper!$C$2:$C$1501,MATCH(10,_Cust_Helper!$F$2:$F$1501,0)),"") -> May | C19: =IF($B19="","",INDEX(_Cust_Helper!$D$2:$D$1501,MATCH(10,_Cust_Helper!$F$2:$F$1501,0))) -> 1 | D19: =IF($B19="","",INDEX(_Cust_Helper!$E$2:$E$1501,MATCH(10,_Cust_Helper!$F$2:$F$1501,0))) -> 464000 | E19: =IF($B19="","",IF($C19=0,0,$D19/$C19)) -> 464000
A22: 📋 Top 10 Customer — Berdasarkan Total Order
A23: Rank | B23: Nama Customer | C23: Connote | D23: Revenue | E23: Rata-rata/Order
A24: 1 | B24: =IFERROR(INDEX(_Cust_Helper!$C$2:$C$1501,MATCH(1,_Cust_Helper!$G$2:$G$1501,0)),"") -> Faradithya Putri Lakcyta | C24: =IF($B24="","",INDEX(_Cust_Helper!$D$2:$D$1501,MATCH(1,_Cust_Helper!$G$2:$G$1501,0))) -> 67 | D24: =IF($B24="","",INDEX(_Cust_Helper!$E$2:$E$1501,MATCH(1,_Cust_Helper!$G$2:$G$1501,0))) -> 1301000 | E24: =IF($B24="","",IF($C24=0,0,$D24/$C24)) -> 19417.91
A25: 2 | B25: =IFERROR(INDEX(_Cust_Helper!$C$2:$C$1501,MATCH(2,_Cust_Helper!$G$2:$G$1501,0)),"") -> Dani Hamdani (Yasashi Japan) | C25: =IF($B25="","",INDEX(_Cust_Helper!$D$2:$D$1501,MATCH(2,_Cust_Helper!$G$2:$G$1501,0))) -> 34 | D25: =IF($B25="","",INDEX(_Cust_Helper!$E$2:$E$1501,MATCH(2,_Cust_Helper!$G$2:$G$1501,0))) -> 521500 | E25: =IF($B25="","",IF($C25=0,0,$D25/$C25)) -> 15338.235
A26: 3 | B26: =IFERROR(INDEX(_Cust_Helper!$C$2:$C$1501,MATCH(3,_Cust_Helper!$G$2:$G$1501,0)),"") -> Michael L. | C26: =IF($B26="","",INDEX(_Cust_Helper!$D$2:$D$1501,MATCH(3,_Cust_Helper!$G$2:$G$1501,0))) -> 29 | D26: =IF($B26="","",INDEX(_Cust_Helper!$E$2:$E$1501,MATCH(3,_Cust_Helper!$G$2:$G$1501,0))) -> 825000 | E26: =IF($B26="","",IF($C26=0,0,$D26/$C26)) -> 28448.276
A27: 4 | B27: =IFERROR(INDEX(_Cust_Helper!$C$2:$C$1501,MATCH(4,_Cust_Helper!$G$2:$G$1501,0)),"") -> Dela Natalia Saputra | C27: =IF($B27="","",INDEX(_Cust_Helper!$D$2:$D$1501,MATCH(4,_Cust_Helper!$G$2:$G$1501,0))) -> 25 | D27: =IF($B27="","",INDEX(_Cust_Helper!$E$2:$E$1501,MATCH(4,_Cust_Helper!$G$2:$G$1501,0))) -> 492000 | E27: =IF($B27="","",IF($C27=0,0,$D27/$C27)) -> 19680
A28: 5 | B28: =IFERROR(INDEX(_Cust_Helper!$C$2:$C$1501,MATCH(5,_Cust_Helper!$G$2:$G$1501,0)),"") -> ratna (gii) | C28: =IF($B28="","",INDEX(_Cust_Helper!$D$2:$D$1501,MATCH(5,_Cust_Helper!$G$2:$G$1501,0))) -> 25 | D28: =IF($B28="","",INDEX(_Cust_Helper!$E$2:$E$1501,MATCH(5,_Cust_Helper!$G$2:$G$1501,0))) -> 441500 | E28: =IF($B28="","",IF($C28=0,0,$D28/$C28)) -> 17660
A29: 6 | B29: =IFERROR(INDEX(_Cust_Helper!$C$2:$C$1501,MATCH(6,_Cust_Helper!$G$2:$G$1501,0)),"") -> Pacificdental_group | C29: =IF($B29="","",INDEX(_Cust_Helper!$D$2:$D$1501,MATCH(6,_Cust_Helper!$G$2:$G$1501,0))) -> 21 | D29: =IF($B29="","",INDEX(_Cust_Helper!$E$2:$E$1501,MATCH(6,_Cust_Helper!$G$2:$G$1501,0))) -> 613500 | E29: =IF($B29="","",IF($C29=0,0,$D29/$C29)) -> 29214.286
A30: 7 | B30: =IFERROR(INDEX(_Cust_Helper!$C$2:$C$1501,MATCH(7,_Cust_Helper!$G$2:$G$1501,0)),"") -> Maryani Yani/ mitra pompa | C30: =IF($B30="","",INDEX(_Cust_Helper!$D$2:$D$1501,MATCH(7,_Cust_Helper!$G$2:$G$1501,0))) -> 20 | D30: =IF($B30="","",INDEX(_Cust_Helper!$E$2:$E$1501,MATCH(7,_Cust_Helper!$G$2:$G$1501,0))) -> 605000 | E30: =IF($B30="","",IF($C30=0,0,$D30/$C30)) -> 30250
A31: 8 | B31: =IFERROR(INDEX(_Cust_Helper!$C$2:$C$1501,MATCH(8,_Cust_Helper!$G$2:$G$1501,0)),"") -> Lunalita (Lutfiyatul Hanifah) | C31: =IF($B31="","",INDEX(_Cust_Helper!$D$2:$D$1501,MATCH(8,_Cust_Helper!$G$2:$G$1501,0))) -> 18 | D31: =IF($B31="","",INDEX(_Cust_Helper!$E$2:$E$1501,MATCH(8,_Cust_Helper!$G$2:$G$1501,0))) -> 521000 | E31: =IF($B31="","",IF($C31=0,0,$D31/$C31)) -> 28944.444
A32: 9 | B32: =IFERROR(INDEX(_Cust_Helper!$C$2:$C$1501,MATCH(9,_Cust_Helper!$G$2:$G$1501,0)),"") -> SJM Paper & Sticker | C32: =IF($B32="","",INDEX(_Cust_Helper!$D$2:$D$1501,MATCH(9,_Cust_Helper!$G$2:$G$1501,0))) -> 16 | D32: =IF($B32="","",INDEX(_Cust_Helper!$E$2:$E$1501,MATCH(9,_Cust_Helper!$G$2:$G$1501,0))) -> 504000 | E32: =IF($B32="","",IF($C32=0,0,$D32/$C32)) -> 31500
A33: 10 | B33: =IFERROR(INDEX(_Cust_Helper!$C$2:$C$1501,MATCH(10,_Cust_Helper!$G$2:$G$1501,0)),"") -> Klinik ESHA Skin Center | C33: =IF($B33="","",INDEX(_Cust_Helper!$D$2:$D$1501,MATCH(10,_Cust_Helper!$G$2:$G$1501,0))) -> 16 | D33: =IF($B33="","",INDEX(_Cust_Helper!$E$2:$E$1501,MATCH(10,_Cust_Helper!$G$2:$G$1501,0))) -> 340000 | E33: =IF($B33="","",IF($C33=0,0,$D33/$C33)) -> 21250
